Traceback (most recent call last):
  File "/home/unicconai/.local/lib/python3.10/site-packages/urllib3/connectionpool.py", line 714, in urlopen
    httplib_response = self._make_request(
  File "/home/unicconai/.local/lib/python3.10/site-packages/urllib3/connectionpool.py", line 415, in _make_request
    conn.request(method, url, **httplib_request_kw)
  File "/usr/lib/python3.10/http/client.py", line 1283, in request
    self._send_request(method, url, body, headers, encode_chunked)
  File "/usr/lib/python3.10/http/client.py", line 1329, in _send_request
    self.endheaders(body, encode_chunked=encode_chunked)
  File "/usr/lib/python3.10/http/client.py", line 1278, in endheaders
    self._send_output(message_body, encode_chunked=encode_chunked)
  File "/usr/lib/python3.10/http/client.py", line 1038, in _send_output
    self.send(msg)
  File "/usr/lib/python3.10/http/client.py", line 976, in send
    self.connect()
  File "/usr/lib/python3/dist-packages/docker/transport/unixconn.py", line 30, in connect
    sock.connect(self.unix_socket)
PermissionError: [Errno 13] Permission denied

During handling of the above exception, another exception occurred:

Traceback (most recent call last):
  File "/home/unicconai/.local/lib/python3.10/site-packages/requests/adapters.py", line 486, in send
    resp = conn.urlopen(
  File "/home/unicconai/.local/lib/python3.10/site-packages/urllib3/connectionpool.py", line 798, in urlopen
    retries = retries.increment(
  File "/home/unicconai/.local/lib/python3.10/site-packages/urllib3/util/retry.py", line 550, in increment
    raise six.reraise(type(error), error, _stacktrace)
  File "/home/unicconai/.local/lib/python3.10/site-packages/urllib3/packages/six.py", line 769, in reraise
    raise value.with_traceback(tb)
  File "/home/unicconai/.local/lib/python3.10/site-packages/urllib3/connectionpool.py", line 714, in urlopen
    httplib_response = self._make_request(
  File "/home/unicconai/.local/lib/python3.10/site-packages/urllib3/connectionpool.py", line 415, in _make_request
    conn.request(method, url, **httplib_request_kw)
  File "/usr/lib/python3.10/http/client.py", line 1283, in request
    self._send_request(method, url, body, headers, encode_chunked)
  File "/usr/lib/python3.10/http/client.py", line 1329, in _send_request
    self.endheaders(body, encode_chunked=encode_chunked)
  File "/usr/lib/python3.10/http/client.py", line 1278, in endheaders
    self._send_output(message_body, encode_chunked=encode_chunked)
  File "/usr/lib/python3.10/http/client.py", line 1038, in _send_output
    self.send(msg)
  File "/usr/lib/python3.10/http/client.py", line 976, in send
    self.connect()
  File "/usr/lib/python3/dist-packages/docker/transport/unixconn.py", line 30, in connect
    sock.connect(self.unix_socket)
urllib3.exceptions.ProtocolError: ('Connection aborted.', PermissionError(13, 'Permission denied'))

During handling of the above exception, another exception occurred:

Traceback (most recent call last):
  File "/usr/lib/python3/dist-packages/docker/api/client.py", line 214, in _retrieve_server_version
    return self.version(api_version=False)["ApiVersion"]
  File "/usr/lib/python3/dist-packages/docker/api/daemon.py", line 181, in version
    return self._result(self._get(url), json=True)
  File "/usr/lib/python3/dist-packages/docker/utils/decorators.py", line 46, in inner
    return f(self, *args, **kwargs)
  File "/usr/lib/python3/dist-packages/docker/api/client.py", line 237, in _get
    return self.get(url, **self._set_request_timeout(kwargs))
  File "/home/unicconai/.local/lib/python3.10/site-packages/requests/sessions.py", line 602, in get
    return self.request("GET", url, **kwargs)
  File "/home/unicconai/.local/lib/python3.10/site-packages/requests/sessions.py", line 589, in request
    resp = self.send(prep, **send_kwargs)
  File "/home/unicconai/.local/lib/python3.10/site-packages/requests/sessions.py", line 703, in send
    r = adapter.send(request, **kwargs)
  File "/home/unicconai/.local/lib/python3.10/site-packages/requests/adapters.py", line 501, in send
    raise ConnectionError(err, request=request)
requests.exceptions.ConnectionError: ('Connection aborted.', PermissionError(13, 'Permission denied'))

During handling of the above exception, another exception occurred:

Traceback (most recent call last):
  File "/usr/bin/docker-compose", line 33, in <module>
    sys.exit(load_entry_point('docker-compose==1.29.2', 'console_scripts', 'docker-compose')())
  File "/usr/lib/python3/dist-packages/compose/cli/main.py", line 81, in main
    command_func()
  File "/usr/lib/python3/dist-packages/compose/cli/main.py", line 200, in perform_command
    project = project_from_options('.', options)
  File "/usr/lib/python3/dist-packages/compose/cli/command.py", line 60, in project_from_options
    return get_project(
  File "/usr/lib/python3/dist-packages/compose/cli/command.py", line 152, in get_project
    client = get_client(
  File "/usr/lib/python3/dist-packages/compose/cli/docker_client.py", line 41, in get_client
    client = docker_client(
  File "/usr/lib/python3/dist-packages/compose/cli/docker_client.py", line 170, in docker_client
    client = APIClient(use_ssh_client=not use_paramiko_ssh, **kwargs)
  File "/usr/lib/python3/dist-packages/docker/api/client.py", line 197, in __init__
    self._version = self._retrieve_server_version()
  File "/usr/lib/python3/dist-packages/docker/api/client.py", line 221, in _retrieve_server_version
    raise DockerException(
docker.errors.DockerException: Error while fetching server API version: ('Connection aborted.', PermissionError(13, 'Permission denied'))
Creating network "kagglex_KaggleX" with the default driver
Building backend
#0 building with "default" instance using docker driver

#1 [internal] load build definition from Dockerfile
#1 transferring dockerfile: 1.61kB done
#1 DONE 0.1s

#2 [internal] load .dockerignore
#2 transferring context: 63B done
#2 DONE 0.1s

#3 [internal] load metadata for docker.io/library/python:3.10.2
#3 ...

#4 [auth] library/python:pull token for registry-1.docker.io
#4 DONE 0.0s

#3 [internal] load metadata for docker.io/library/python:3.10.2
#3 DONE 3.8s

#5 [internal] load build context
#5 transferring context: 120.74kB 0.0s done
#5 DONE 0.1s

#6 [cache 1/5] FROM docker.io/library/python:3.10.2@sha256:3204faabc2f0b5e0939bdb8b29079a2a330c38dee92a22482a9ed449c5649a55
#6 resolve docker.io/library/python:3.10.2@sha256:3204faabc2f0b5e0939bdb8b29079a2a330c38dee92a22482a9ed449c5649a55 0.1s done
#6 sha256:3204faabc2f0b5e0939bdb8b29079a2a330c38dee92a22482a9ed449c5649a55 2.14kB / 2.14kB done
#6 sha256:17e2d81e5757980ee40742d77dd5d3e1a69ad0d6dacb13064e1b018a6664ec72 2.22kB / 2.22kB done
#6 sha256:178dcaa62b393b539abc8b866c39be81e8ade01786880dc5d17ce3fe02426dbb 8.55kB / 8.55kB done
#6 CANCELED

#7 [cache 2/5] RUN apt-get update &&     apt-get install -y --no-install-recommends build-essential ffmpeg libsm6 libxext6 cmake &&     apt-get clean
#7 CACHED

#8 [cache 3/5] COPY requirements.txt requirements.txt
#8 CACHED

#9 [cache 4/5] RUN pip install -r requirements.txt
#9 CACHED

#10 [cache 5/5] COPY ./.cache ./.cache
#10 ERROR: failed to calculate checksum of ref e4028716-a523-40ea-9105-e5a4b2b7318e::k5iwd6vi5y6gnj102oq5052ij: "/.cache": not found
------
 > [cache 5/5] COPY ./.cache ./.cache:
------
Dockerfile:41
--------------------
  39 |     RUN pip install -r requirements.txt
  40 |     
  41 | >>> COPY ./.cache ./.cache
  42 |     
  43 |     # Second stage: Copy the rest of the files and build the final image
--------------------
ERROR: failed to solve: failed to compute cache key: failed to calculate checksum of ref e4028716-a523-40ea-9105-e5a4b2b7318e::k5iwd6vi5y6gnj102oq5052ij: "/.cache": not found
Service 'backend' failed to build : Build failed
